<robot name="buff_digit" >

  <material name="black">
    <color rgba="0.2 0.2 0.2 1.0"/>
  </material>
  <material name="blue">
    <color rgba="1.0 1.0 1.0 1.0"/>
  </material>
  <material name="green">
    <color rgba="1.0 1.0 1.0 1.0"/>
  </material>
  <material name="grey">
    <color rgba="0.4 0.4 0.4 1.0"/>
  </material>
  <material name="silver">
    <color rgba="0.913725490196 0.913725490196 0.847058823529 1.0"/>
  </material>
  <material name="orange">
    <color rgba="1.0 1.0 1.0 1.0"/>
  </material>
  <material name="brown">
    <color rgba="0.870588235294 0.811764705882 0.764705882353 1.0"/>
  </material>
  <material name="red">
    <color rgba="1.0 1.0 1.0 1.0"/>
  </material>
  <material name="white">
    <color rgba="1.0 1.0 1.0 1.0"/>
  </material>
  <material name="scarlet">
    <color rgba="0.28 0.82 0.8 1"/>
  </material>




<link name="torso">
    <inertial>
      <origin rpy="0 0 0" xyz="0.001637 0.0002 0.259547"/>
      <mass value="0.028392"/>
      <inertia ixx="0.376284" ixy="-8.8e-05" ixz="0.008378" iyy="0.342655" iyz="6.7e-05" izz="0.100648"/>
    </inertial>
    <visual>
      <origin rpy="0 0 0" xyz="0 0 0"/>
      <geometry>
        <mesh filename="stl/torso.stl"/>
      </geometry>
      <material name="scarlet"/> 
    </visual>
    <collision>
      <origin rpy="0 0 0" xyz="0 0 0"/>
      <geometry>
        <mesh filename="stl/torso.stl"/>
      </geometry>
    </collision>
  </link>


 
  <!-- LEGS -->
  <link name="left_hip_roll">
    <inertial>
      <origin rpy="0 0 0" xyz="-0.001967 0.000244 0.031435"/>
      <mass value="0.915088"/>
      <inertia ixx="0.001017" ixy="-3e-06" ixz="1.3e-05" iyy="0.001148" iyz="-4e-06" izz="0.000766"/>
    </inertial>
    <visual>
      <origin rpy="0 0 0" xyz="0 0 0"/>
      <geometry>
        <mesh filename="stl/hip-yaw-housing.stl"/>
      </geometry>
      <material name="grey">
        <color rgba="0.35 0.35 0.35 1"/>
      </material>
    </visual>
    <collision>
      <origin rpy="0 0 0" xyz="0 0 0"/>
      <geometry>
        <mesh filename="stl/hip-yaw-housing.stl"/>
      </geometry>
    </collision>
  </link>
  <link name="left_hip_yaw">
    <inertial>
      <origin rpy="0 0 0" xyz="1e-05 -0.001945 0.042033"/>
      <mass value="0.818753"/>
      <inertia ixx="0.001627" ixy="-1e-06" ixz="2e-06" iyy="0.001929" iyz="5.3e-05" izz="0.00077"/>
    </inertial>
    <visual>
      <origin rpy="0 0 0" xyz="0 0 0"/>
      <geometry>
        <mesh filename="stl/hip-pitch-housing.stl"/>
      </geometry>
      <material name="light_grey">
        <color rgba="0.75 0.75 0.75 1"/>
      </material>
    </visual>
     <collision>
      <origin rpy="0 0 0" xyz="0 0 0"/>
      <geometry>
        <mesh filename="stl/hip-pitch-housing.stl"/>
      </geometry>
    </collision>
  </link>
  <link name="left_hip_pitch">
    <inertial>
      <origin rpy="0 0 0" xyz="0.060537 0.000521 -0.038857"/>
      <mass value="6.244279"/>
      <inertia ixx="0.011533" ixy="-0.000171" ixz="0.000148" iyy="0.033345" iyz="0.000178" izz="0.033958"/>
    </inertial>
    <visual>
      <origin rpy="0 0 0" xyz="0 0 0"/>
      <geometry>
        <mesh filename="stl/hip-pitch.stl"/>
      </geometry>
      <material name="scarlet"/> 
    </visual>
    <collision>
      <origin rpy="0 0 0" xyz="0 0 0"/>
      <geometry>
        <mesh filename="stl/hip-pitch.stl"/>
      </geometry>
    </collision>
  </link>
  <link name="left_knee">
    <inertial>
      <origin rpy="0 0 0" xyz="0.045641 0.042154 0.001657"/>
      <mass value="1.227077"/>
      <inertia ixx="0.002643" ixy="-0.001832" ixz="6.6e-05" iyy="0.005098" iyz="4.5e-05" izz="0.007019"/>
    </inertial>
    <visual>
      <origin rpy="0 0 0" xyz="0 0 0"/>
      <geometry>
        <mesh filename="stl/knee.stl"/>
      </geometry>
      <material name="grey">
        <color rgba="0.35 0.35 0.35 1"/>
      </material>
    </visual>
    <collision>
      <origin rpy="0 0 0" xyz="0 0 0"/>
      <geometry>
        <mesh filename="stl/knee.stl"/>
      </geometry>
    </collision>
  </link>
  <link name="left_shin">
    <inertial>
      <origin rpy="0 0 0" xyz="0.174265 0.010265 0.00107"/>
      <mass value="0.895793"/>
      <inertia ixx="0.001128" ixy="0.001098" ixz="0.000196" iyy="0.022492" iyz="-3e-06" izz="0.022793"/>
    </inertial>
    <visual>
      <origin rpy="0 0 0" xyz="0 0 0"/>
      <geometry>
        <mesh filename="stl/shin.stl"/>
      </geometry>
      <material name="scarlet"/> 
    </visual>
    <collision>
      <origin rpy="0 0 0" xyz="0 0 0"/>
      <geometry>
        <mesh filename="stl/shin.stl"/>
      </geometry>
    </collision>
  </link>
 <link name="left_tarsus">
    <inertial>
      <origin rpy="0 0 0" xyz="0.000932 -0.029183 0.000678"/>
      <mass value="1.322865"/>
      <inertia ixx="0.000932" ixy="0.00061" ixz="0.000102" iyy="0.016409" iyz="9e-06" izz="0.016501"/>
    </inertial>
    <visual>
      <origin rpy="0 0 0" xyz="0 0 0"/>
      <geometry>
        <mesh filename="stl/tarsus.stl"/>
      </geometry>
      <material name="grey">
        <color rgba="0.35 0.35 0.35 1"/>
      </material>
    </visual>
    <collision>
      <origin rpy="0 0 0" xyz="0 0 0"/>
      <geometry>
        <!-- <mesh filename="stl/tarsus.stl"/> -->
        <box size="0.01 0.01 0.01"/>
      </geometry>
    </collision>
  </link>
  <link name="left_toe_pitch">
    <inertial>
      <origin rpy="0 0 0" xyz="-0.000141 2e-06 3e-06"/>
      <mass value="0.043881"/>
      <inertia ixx="5e-06" ixy="0" ixz="0" iyy="8e-06" iyz="0" izz="5e-06"/>
    </inertial>
    <visual>
      <origin rpy="0 0 0" xyz="0 0 0"/>
      <geometry>
        <mesh filename="stl/toe-pitch.stl"/>
      </geometry>
      <material name="light_grey">
        <color rgba="0.75 0.75 0.75 1"/>
      </material>
    </visual>
    <collision>
      <origin rpy="0 0 0" xyz="0 0 0"/>
      <geometry>
        <!-- <mesh filename="stl/toe-pitch.stl"/> -->
        <box size="0.001 0.001 0.001"/>
      </geometry>
    </collision>
  </link>
  <link name="left_toe_roll">
    <inertial>
      <origin rpy="0 0 0" xyz="9e-06 -0.028084 -0.023204"/>
      <mass value="0.531283"/>
      <inertia ixx="0.00187" ixy="0" ixz="0" iyy="0.001616" iyz="0.000566" izz="0.000843"/>
    </inertial>
    <visual>
      <origin rpy="0 0 0" xyz="0 0 0"/>
      <geometry>
        <mesh filename="stl/toe-roll.stl"/>
      </geometry>
      <material name="light_grey">
        <color rgba="0.75 0.75 0.75 1"/>
      </material>
    </visual>
    <collision>
      <origin rpy="0 0 0" xyz="0 0 0"/>
      <geometry>
        <!-- <mesh filename="stl/toe-roll.stl"/> -->
        <box size="0.01 0.01 0.01"/>
      </geometry>
    </collision>
  </link>



  <!-- left arm -->
    
 <joint name="left_attach_to_torso" type="fixed">
    <origin rpy="0 0 0" xyz="-0.001 0.12 0.4"/>
     <parent link="torso"/>
    <child link="left_attach"/>
   </joint>

<link name="left_attach">
    <inertial>
      <origin rpy="0 0 0" xyz="0 0 0"/>
       <mass value=".01"/>
       <inertia ixx="0" ixy="0" ixz="0" iyy="0" iyz="0" izz="0"/>
    </inertial>
    <visual>
      <origin rpy="1.5707  0 0" xyz="0 0 0"/>
      <geometry>
        <cylinder radius="0.025" length="0.1"/>
      </geometry>
       <material name="grey"/>
    </visual>
    <collision>
      <origin rpy="1.5707 0 0" xyz="0 0 0"/>
      <geometry>
        <cylinder radius="0.025" length="0.1"/>
      </geometry>
    </collision>
  </link>

  <joint name="left_arm_to_left_attach" type="fixed">
    <origin rpy="0 0 0" xyz="0 0 0"/>
     <parent link="left_attach"/>
    <child link="left_jlink0"/>
   </joint>

 <link name="left_jlink0">
    <inertial>
      <origin rpy="0 0 0" xyz="0 0 0"/>
       <mass value=".01"/>
       <inertia ixx="0" ixy="0" ixz="0" iyy="0" iyz="0" izz="0"/>
    </inertial>
    <visual>
      <origin rpy="1.5707  0 0" xyz="0 0 0"/>
      <geometry>
        <cylinder radius="0.025" length="0.025"/>
      </geometry>
       <material name="grey"/>
    </visual>
    <collision>
      <origin rpy="1.5707 0 0" xyz="0 0 0"/>
      <geometry>
        <cylinder radius="0.025" length="0.025"/>
      </geometry>
    </collision>
  </link>

  <link name="left_link1">
    <inertial>
      <origin rpy="0 0 0" xyz="0 0 0"/>
       <mass value=".000000001"/>
       <inertia ixx="0" ixy="0" ixz="0" iyy="0" iyz="0" izz="0"/>
    </inertial>
    <visual>
      <origin rpy="1.5707 0 0" xyz="0 0 0"/>
      <geometry>
       <cylinder radius="0.0125" length="0.08"/>
       <!-- <box size = "0.025 0.08 0.025"/> -->
      </geometry>
       <material name="scarlet"/> 
    </visual>
    <collision>
      <origin rpy="1.5707 0 0" xyz="0 0 0"/>
      <geometry>
       <cylinder radius="0.0125" length="0.08"/>
      </geometry>
    </collision>
  </link>

  <joint name="left_joint1f" type="revolute"> 
    <parent link="left_jlink0"/>
    <child link="left_link1"/>
    <origin rpy="0 0 0" xyz="0 0.04 0.0"/>  
    <axis xyz="0 1 0"/>
    <limit lower="-3.1415" upper="3.1415" effort="1.4" velocity="0.25"/>
  </joint>

  <link name="left_jlink1">
    <inertial>
      <origin rpy="0 0 0" xyz="0 0 0"/>
       <mass value=".01"/>
       <inertia ixx="0" ixy="0" ixz="0" iyy="0" iyz="0" izz="0"/>
    </inertial>
    <visual>
      <origin rpy="0 1.5707 0" xyz="0 0 0"/>
      <geometry>
        <cylinder radius="0.025" length="0.025"/>
      </geometry>
       <material name="grey"/>
    </visual>
    <collision>
      <origin rpy="0 1.5707 0" xyz="0 0 0"/>
      <geometry>
        <cylinder radius="0.025" length="0.025"/>
      </geometry>
    </collision>
</link>

  <joint name="left_joint1" type="revolute">
    <parent link="left_link1"/>
    <child link="left_jlink1"/>
    <origin rpy="0 0 0" xyz="0 0.04 0"/> 
    <axis xyz="1 0 0"/>
    <limit lower="-3.1415" upper="3.1415" effort="1.4" velocity="0.25"/>  
  </joint>

  <link name="left_link2">
    <inertial>
      <origin rpy="0 0 0" xyz="0 0 0"/>
       <mass value=".000000001"/>
       <inertia ixx="0" ixy="0" ixz="0" iyy="0" iyz="0" izz="0"/>
    </inertial>
    <visual>
      <origin rpy="0 0 0" xyz="0 0 0"/>
      <geometry>
       <cylinder radius="0.03" length="0.2"/>
      </geometry>
       <material name="scarlet"/> 
    </visual>
    <collision>
      <origin rpy="0 0 0" xyz="0 0 0"/>
      <geometry>
       <cylinder radius="0.03" length="0.2"/>
      </geometry>
    </collision>
</link>

<joint name="left_joint2f" type="fixed">
    <parent link="left_jlink1"/>
    <child link="left_link2"/>
    <origin rpy="0 0 0" xyz="0 0  -0.1"/> 
    <!-- <axis xyz="1 0 0"/>
    <limit lower="-3.1415" upper="3.1415" effort="1.4" velocity="0.25"/> -->    
</joint>

<link name="left_jlink2">
    <inertial>
      <origin rpy="0 0 0" xyz="0 0 0"/>
       <mass value=".01"/>
       <inertia ixx="0" ixy="0" ixz="0" iyy="0" iyz="0" izz="0"/>
    </inertial>
    <visual>
      <origin rpy="0 0 0" xyz="0 0 0"/>
      <geometry>
        <cylinder radius="0.025" length="0.025"/>
      </geometry>
       <material name="grey"/>
    </visual>
    <collision>
      <origin rpy="0 0 0" xyz="0 0 0"/>
      <geometry>
        <cylinder radius="0.025" length="0.025"/>
      </geometry>
    </collision>
</link>

<joint name="left_joint2" type="fixed">
    <parent link="left_link2"/>
    <child link="left_jlink2"/>
    <origin rpy="0 0 0" xyz="0 0 -0.1"/> 
    <!-- <axis xyz="0 0 1"/>
    <limit lower="-3.1415" upper="3.1415" effort="1.4" velocity="0.25"/>   -->
  </joint>

  <link name="left_link3">
    <inertial>
      <origin rpy="0 0 0" xyz="0 0 0"/>
       <mass value=".000000001"/>
       <inertia ixx="0" ixy="0" ixz="0" iyy="0" iyz="0" izz="0"/>
    </inertial>
    <visual>
      <origin rpy="0 0 0" xyz="0 0 0"/>
      <geometry>
       <cylinder radius="0.03" length="0.2"/>
      </geometry>
       <material name="grey"/> 
    </visual>
    <collision>
      <origin rpy="0 0 0" xyz="0 0 0"/>
      <geometry>
       <cylinder radius="0.03" length="0.2"/>
      </geometry>
    </collision>
</link>

<joint name="left_joint3f" type="fixed">
    <parent link="left_jlink2"/>
    <child link="left_link3"/>
    <origin rpy="0 0 0" xyz="0 0  -0.1035"/>   
</joint>

<link name="left_jlink3">
    <inertial>
      <origin rpy="0 0 0" xyz="0 0 0"/>
       <mass value=".01"/>
       <inertia ixx="0" ixy="0" ixz="0" iyy="0" iyz="0" izz="0"/>
    </inertial>
    <visual>
      <origin rpy="0 1.5707 0" xyz="0 0 0"/>
      <geometry>
        <cylinder radius="0.025" length="0.025"/>
      </geometry>
       <material name="scarlet"/>
    </visual>
    <collision>
      <origin rpy="0 1.5707 0" xyz="0 0 0"/>
      <geometry>
        <cylinder radius="0.025" length="0.025"/>
      </geometry>
    </collision>
</link>

<joint name="left_joint3" type="revolute">
    <parent link="left_link3"/>
    <child link="left_jlink3"/>
    <origin rpy="0 0 0" xyz="0 0.0 -0.1"/> 
    <axis xyz="1 0 0"/>
    <limit lower="-3.1415" upper="3.1415" effort="1.4" velocity="0.25"/>  
  </joint>

  <link name="left_link4">
    <inertial>
      <origin rpy="0 0 0" xyz="0 0 0"/>
       <mass value=".000000001"/>
       <inertia ixx="0" ixy="0" ixz="0" iyy="0" iyz="0" izz="0"/>
    </inertial>
    <visual>
      <origin rpy="0 0 0" xyz="0 0 0"/>
      <geometry>
       <cylinder radius="0.03" length="0.4"/>
      </geometry>
       <material name="silver"/> 
    </visual>
    <collision>
      <origin rpy="0 0 0" xyz="0 0 0"/>
      <geometry>
       <cylinder radius="0.03" length="0.4"/>
      </geometry>
    </collision>
</link>

<joint name="left_joint4f" type="fixed">
    <parent link="left_jlink3"/>
    <child link="left_link4"/>
    <origin rpy="0 0 0" xyz="0 0  -0.2"/>   
</joint>

<link name="left_jlink4">
    <inertial>
      <origin rpy="0 0 0" xyz="0.107996 0.000521 -0.017765"/>
      <mass value="0.550582"/>
      <inertia ixx="0.000476" ixy="-2.9e-05" ixz="0.001403" iyy="0.009564" iyz="-1.5e-05" izz="-9e-06"/>
    </inertial>
    <visual>
      <origin rpy="0 0 0 " xyz="0 0 0"/>
      <geometry>
        <cylinder radius="0.025" length="0.025"/>
      </geometry>
      <material name="scarlet"/> 
    </visual>
    <collision>
      <origin rpy="0 0 0" xyz="0 0 0"/>
      <geometry>
        <cylinder radius="0.025" length="0.025"/>
      </geometry>
    </collision>
</link>

<joint name="left_joint4" type="revolute">
    <origin rpy="0 0 0" xyz="0.0 0.0 -0.2"/>
    <parent link="left_link4"/>
    <child link="left_jlink4"/>
    <axis xyz="0 0 1"/>
    <limit effort="1.4" lower="-1.57" upper="1.57" velocity="10"/>
  </joint>

<link name="left_wrist">
    <inertial>
      <origin rpy="0 0 0" xyz="0.107996 0.000521 -0.017765"/>
      <mass value="0.550582"/>
      <inertia ixx="0.000476" ixy="-2.9e-05" ixz="0.001403" iyy="0.009564" iyz="-1.5e-05" izz="-9e-06"/>
    </inertial>
    <visual>
      <origin rpy="0 1.5707 1.5707 " xyz="0 0 0"/>
      <geometry>
        <cylinder radius="0.025" length="0.05"/>
      </geometry>
      <material name="grey"/>
    </visual>
    <collision>
      <origin rpy="0 1.5707 1.5707" xyz="0 0 0"/>
      <geometry>
        <cylinder radius="0.025" length="0.05"/>
      </geometry>
    </collision>
  </link>
  <joint name="left_wrist_joint" type="revolute">
    <origin rpy="0 1.5707 0" xyz="0.0 0.0 -0.025"/>
    <parent link="left_jlink4"/>
    <child link="left_wrist"/>
    <axis xyz="0 1 0"/>
    <limit effort="1.4" lower="-1.57" upper="1.57" velocity="10"/>
  </joint>

  <link name="left_gripper_base">
    <inertial>
      <origin rpy="0 0 0" xyz="0 0 0"/>
      <mass value="0.2"/>
      <inertia ixx="0.0001" ixy="0" ixz="0" iyy="0.0001" iyz="0" izz="0.0001"/>
    </inertial>
    <visual>
      <origin rpy="0 1.5707 0" xyz="0 0 0"/>
      <geometry>
        <!-- <mesh filename="/home/bill/garage/kfp_v2/morpheus/models/yumi_description/meshes/gripper/base.stl"/> -->
        <cylinder radius="0.04" length="0.1"/>
      </geometry>
      <material name="Light_Grey"/>
    </visual>
    <collision>
      <origin rpy="0 1.5707 0" xyz="0 0 0"/>
      <geometry>
        <!-- <mesh filename="/home/bill/garage/kfp_v2/morpheus/models/yumi_description/meshes/gripper/coarse/base.stl"/> -->
       <cylinder radius="0.04" length="0.1"/>
      </geometry>
      <material name="Light_Grey"/>
    </collision>
  </link>

  <joint name="gripper_left_wrist_joint" type="revolute">
    <origin rpy="0 0 0" xyz="0.07 0 0"/>
    <parent link="left_wrist"/>
    <child link="left_gripper_base"/>
    <axis xyz="1 0 0"/>
    <limit effort="1.4" lower="-1.57" upper="1.57" velocity="10"/>
  </joint>

  <link name="left_gripper_ee">
    <inertial>
      <origin rpy="0 0 0" xyz="0 0 0"/>
      <mass value="0.2"/>
      <inertia ixx="0.0001" ixy="0" ixz="0" iyy="0.0001" iyz="0" izz="0.0001"/>
    </inertial>
    <visual>
      <origin rpy="0 1.5707 0" xyz="0 0 0"/>
      <geometry>        
       <cylinder radius="0.025" length="0.025"/>
      </geometry>
      <material name="scarlet"/>
    </visual>
    <collision>
      <origin rpy="0 1.5707 0" xyz="0 0 0"/>
      <geometry>
       <cylinder radius="0.025" length="0.025"/>
      </geometry> 
    </collision>
  </link>
  <joint name="left_gripper_baseee_to_gripper_base" type="fixed">
    <origin rpy="0 0 0" xyz="0.05125 0.0 0"/>
    <parent link="left_gripper_base"/>
    <child link="left_gripper_ee"/>
  </joint>










<!-- right leg -->
  <link name="right_hip_roll">
    <inertial>
      <origin rpy="0 0 0" xyz="-0.001967 -0.000244 0.031435"/>
      <mass value="0.915088"/>
      <inertia ixx="0.001017" ixy="3e-06" ixz="1.3e-05" iyy="0.001148" iyz="4e-06" izz="0.000766"/>
    </inertial>
    <visual>
      <origin rpy="0 0 0" xyz="0 0 0"/>
      <geometry>
        <mesh filename="stl/hip-yaw-housing.stl" scale="1 -1 1"/>
      </geometry>
      <material name="grey">
        <color rgba="0.35 0.35 0.35 1"/>
      </material>
    </visual>
    <collision>
      <origin rpy="0 0 0" xyz="0 0 0"/>
      <geometry>
        <mesh filename="stl/hip-yaw-housing.stl" scale="1 -1 1"/>
      </geometry>
    </collision>
  </link>
  <link name="right_hip_yaw">
    <inertial>
      <origin rpy="0 0 0" xyz="1e-05 0.001945 0.042033"/>
      <mass value="0.818753"/>
      <inertia ixx="0.001627" ixy="1e-06" ixz="2e-06" iyy="0.001929" iyz="-5.3e-05" izz="0.00077"/>
    </inertial>
    <visual>
      <origin rpy="0 0 0" xyz="0 0 0"/>
      <geometry>
        <mesh filename="stl/hip-pitch-housing.stl" scale="1 -1 1"/>
      </geometry>
      <material name="light_grey">
        <color rgba="0.75 0.75 0.75 1"/>
      </material>
    </visual>
    <collision>
      <origin rpy="0 0 0" xyz="0 0 0"/>
      <geometry>
        <mesh filename="stl/hip-pitch-housing.stl" scale="1 -1 1"/>
      </geometry>
    </collision>
  </link>
  <link name="right_hip_pitch">
    <inertial>
      <origin rpy="0 0 0" xyz="0.060537 -0.000521 -0.038857"/>
      <mass value="6.244279"/>
      <inertia ixx="0.011533" ixy="0.000171" ixz="0.000148" iyy="0.033345" iyz="-0.000178" izz="0.033958"/>
    </inertial>
    <visual>
      <origin rpy="0 0 0" xyz="0 0 0"/>
      <geometry>
        <mesh filename="stl/hip-pitch.stl" scale="1 -1 1"/>
      </geometry>
      <material name="scarlet"/> 
    </visual>
    <collision>
      <origin rpy="0 0 0" xyz="0 0 0"/>
      <geometry>
        <mesh filename="stl/hip-pitch.stl" scale="1 -1 1"/>
      </geometry>
    </collision>
  </link>
  <link name="right_knee">
    <inertial>
      <origin rpy="0 0 0" xyz="0.045641 -0.042154 0.001657"/>
      <mass value="1.227077"/>
      <inertia ixx="0.002643" ixy="0.001832" ixz="6.6e-05" iyy="0.005098" iyz="-4.5e-05" izz="0.007019"/>
    </inertial>
    <visual>
      <origin rpy="0 0 0" xyz="0 0 0"/>
      <geometry>
        <mesh filename="stl/knee.stl" scale="1 -1 1"/>
      </geometry>
      <material name="grey">
        <color rgba="0.35 0.35 0.35 1"/>
      </material>
    </visual>
    <collision>
      <origin rpy="0 0 0" xyz="0 0 0"/>
      <geometry>
        <mesh filename="stl/knee.stl" scale="1 -1 1"/>
      </geometry>
    </collision>
  </link>
  <link name="right_shin">
    <inertial>
      <origin rpy="0 0 0" xyz="0.174265 -0.010265 0.00107"/>
      <mass value="0.895793"/>
      <inertia ixx="0.001128" ixy="-0.001098" ixz="0.000196" iyy="0.022492" iyz="3e-06" izz="0.022793"/>
    </inertial>
    <visual>
      <origin rpy="0 0 0" xyz="0 0 0"/>
      <geometry>
        <mesh filename="stl/shin.stl" scale="1 -1 1"/>
      </geometry>
      <material name="scarlet"/> 
    </visual>
    <collision>
      <origin rpy="0 0 0" xyz="0 0 0"/>
      <geometry>
        <mesh filename="stl/shin.stl" scale="1 -1 1"/>
      </geometry>
    </collision>
  </link>
  <link name="right_tarsus">
    <inertial>
      <origin rpy="0 0 0" xyz="0.000932 0.029183 0.000678"/>
      <mass value="1.322865"/>
      <inertia ixx="0.000932" ixy="-0.00061" ixz="0.000102" iyy="0.016409" iyz="-9e-06" izz="0.016501"/>
    </inertial>
    <visual>
      <origin rpy="0 0 0" xyz="0 0 0"/>
      <geometry>
        <mesh filename="stl/tarsus.stl" scale="1 -1 1"/>
      </geometry>
      <material name="grey">
        <color rgba="0.35 0.35 0.35 1"/>
      </material>
    </visual>
    <collision>
      <origin rpy="0 0 0" xyz="0 0 0"/>
      <geometry>
         <box size="0.01 0.01 0.01"/>
      </geometry>
    </collision>
  </link>
  <link name="right_toe_pitch">
    <inertial>
      <origin rpy="0 0 0" xyz="-0.000141 -2e-06 3e-06"/>
      <mass value="0.043881"/>
      <inertia ixx="5e-06" ixy="0" ixz="0" iyy="8e-06" iyz="0" izz="5e-06"/>
    </inertial>
    <visual>
      <origin rpy="0 0 0" xyz="0 0 0"/>
      <geometry>
        <mesh filename="stl/toe-pitch.stl" scale="1 -1 1"/>
      </geometry>
      <material name="light_grey">
        <color rgba="0.75 0.75 0.75 1"/>
      </material>
    </visual>
    <collision>
      <origin rpy="0 0 0" xyz="0 0 0"/>
      <geometry>
         <box size="0.001 0.001 0.001"/>
      </geometry>
    </collision>
  </link>
  <link name="right_toe_roll">
    <inertial>
      <origin rpy="0 0 0" xyz="9e-06 0.028084 -0.023204"/>
      <mass value="0.531283"/>
      <inertia ixx="0.00187" ixy="0" ixz="0" iyy="0.001616" iyz="-0.000566" izz="0.000843"/>
    </inertial>
    <visual>
      <origin rpy="0 0 0" xyz="0 0 0"/>
      <geometry>
        <mesh filename="stl/toe-roll.stl" scale="1 -1 1"/>
      </geometry>
      <material name="light_grey">
        <color rgba="0.75 0.75 0.75 1"/>
      </material>
    </visual>
    <collision>
      <origin rpy="0 0 0" xyz="0 0 0"/>
      <geometry>
         <box size="0.01 0.01 0.01"/>
      </geometry>
    </collision>
  </link>




  <!-- right arm -->
   <joint name="right_attach_to_torso" type="fixed">
    <origin rpy="0 0 0" xyz="-0.001 -0.12 0.4"/>
     <parent link="torso"/>
    <child link="right_attach"/>
   </joint>

   <link name="right_attach">
    <inertial>
      <origin rpy="0 0 0" xyz="0 0 0"/>
       <mass value=".01"/>
       <inertia ixx="0" ixy="0" ixz="0" iyy="0" iyz="0" izz="0"/>
    </inertial>
    <visual>
      <origin rpy="1.5707  0 0" xyz="0 0 0"/>
      <geometry>
        <cylinder radius="0.025" length="0.1"/>
      </geometry>
       <material name="grey"/>
    </visual>
    <collision>
      <origin rpy="1.5707 0 0" xyz="0 0 0"/>
      <geometry>
        <cylinder radius="0.025" length="0.1"/>
      </geometry>
    </collision>
  </link>

  <joint name="right_arm_to_right_attach" type="fixed">
    <origin rpy="0 0 0" xyz="0 0 0"/>
     <parent link="right_attach"/>
    <child link="right_jlink0"/>
   </joint>



  <link name="right_jlink0">
    <inertial>
      <origin rpy="0 0 0" xyz="0 0 0"/>
       <mass value=".01"/>
       <inertia ixx="0" ixy="0" ixz="0" iyy="0" iyz="0" izz="0"/>
    </inertial>
    <visual>
      <origin rpy="1.5707  0 0" xyz="0 0 0"/>
      <geometry>
        <cylinder radius="0.025" length="0.025"/>
      </geometry>
       <material name="grey"/>
    </visual>
    <collision>
      <origin rpy="1.5707 0 0" xyz="0 0 0"/>
      <geometry>
        <cylinder radius="0.025" length="0.025"/>
      </geometry>
    </collision>
  </link>

  <link name="right_link1">
    <inertial>
      <origin rpy="0 0 0" xyz="0 0 0"/>
       <mass value=".000000001"/>
       <inertia ixx="0" ixy="0" ixz="0" iyy="0" iyz="0" izz="0"/>
    </inertial>
    <visual>
      <origin rpy="1.5707 0 0" xyz="0 0 0"/>
      <geometry>
       <cylinder radius="0.0125" length="0.08"/>
       <!-- <box size = "0.025 0.08 0.025"/> -->
      </geometry>
       <material name="scarlet"/> 
    </visual>
    <collision>
      <origin rpy="1.5707 0 0" xyz="0 0 0"/>
      <geometry>
       <cylinder radius="0.0125" length="0.08"/>
      </geometry>
    </collision>
  </link>

  <joint name="right_joint1f" type="revolute"> 
    <parent link="right_jlink0"/>
    <child link="right_link1"/>
    <origin rpy="0 0 0" xyz="0 -0.04 0.0"/>  
    <axis xyz="0 1 0"/>
    <limit lower="-3.1415" upper="3.1415" effort="1.4" velocity="0.25"/>
  </joint>

  <link name="right_jlink1">
    <inertial>
      <origin rpy="0 0 0" xyz="0 0 0"/>
       <mass value=".01"/>
       <inertia ixx="0" ixy="0" ixz="0" iyy="0" iyz="0" izz="0"/>
    </inertial>
    <visual>
      <origin rpy="0 1.5707 0" xyz="0 0 0"/>
      <geometry>
        <cylinder radius="0.025" length="0.025"/>
      </geometry>
       <material name="grey"/>
    </visual>
    <collision>
      <origin rpy="0 1.5707 0" xyz="0 0 0"/>
      <geometry>
        <cylinder radius="0.025" length="0.025"/>
      </geometry>
    </collision>
</link>

  <joint name="right_joint1" type="revolute">
    <parent link="right_link1"/>
    <child link="right_jlink1"/>
    <origin rpy="0 0 0" xyz="0 -0.04 0"/> 
    <axis xyz="1 0 0"/>
    <limit lower="-3.1415" upper="3.1415" effort="1.4" velocity="0.25"/>  
  </joint>

  <link name="right_link2">
    <inertial>
      <origin rpy="0 0 0" xyz="0 0 0"/>
       <mass value=".000000001"/>
       <inertia ixx="0" ixy="0" ixz="0" iyy="0" iyz="0" izz="0"/>
    </inertial>
    <visual>
      <origin rpy="0 0 0" xyz="0 0 0"/>
      <geometry>
       <cylinder radius="0.03" length="0.2"/>
      </geometry>
       <material name="scarlet"/> 
    </visual>
    <collision>
      <origin rpy="0 0 0" xyz="0 0 0"/>
      <geometry>
       <cylinder radius="0.03" length="0.2"/>
      </geometry>
    </collision>
</link>

<joint name="right_joint2f" type="fixed">
    <parent link="right_jlink1"/>
    <child link="right_link2"/>
    <origin rpy="0 0 0" xyz="0 0  -0.1"/>      
</joint>

<link name="right_jlink2">
    <inertial>
      <origin rpy="0 0 0" xyz="0 0 0"/>
       <mass value=".01"/>
       <inertia ixx="0" ixy="0" ixz="0" iyy="0" iyz="0" izz="0"/>
    </inertial>
    <visual>
      <origin rpy="0 0 0" xyz="0 0 0"/>
      <geometry>
        <cylinder radius="0.025" length="0.025"/>
      </geometry>
       <material name="grey"/>
    </visual>
    <collision>
      <origin rpy="0 0 0" xyz="0 0 0"/>
      <geometry>
        <cylinder radius="0.025" length="0.025"/>
      </geometry>
    </collision>
</link>

<joint name="right_joint2" type="fixed">
    <parent link="right_link2"/>
    <child link="right_jlink2"/>
    <origin rpy="0 0 0" xyz="0 0 -0.1"/>  
  </joint>

  <link name="right_link3">
    <inertial>
      <origin rpy="0 0 0" xyz="0 0 0"/>
       <mass value=".000000001"/>
       <inertia ixx="0" ixy="0" ixz="0" iyy="0" iyz="0" izz="0"/>
    </inertial>
    <visual>
      <origin rpy="0 0 0" xyz="0 0 0"/>
      <geometry>
       <cylinder radius="0.03" length="0.2"/>
      </geometry>
       <material name="grey"/> 
    </visual>
    <collision>
      <origin rpy="0 0 0" xyz="0 0 0"/>
      <geometry>
       <cylinder radius="0.03" length="0.2"/>
      </geometry>
    </collision>
</link>

<joint name="right_joint3f" type="fixed">
    <parent link="right_jlink2"/>
    <child link="right_link3"/>
    <origin rpy="0 0 0" xyz="0 0  -0.1035"/>   
</joint>

<link name="right_jlink3">
    <inertial>
      <origin rpy="0 0 0" xyz="0 0 0"/>
       <mass value=".01"/>
       <inertia ixx="0" ixy="0" ixz="0" iyy="0" iyz="0" izz="0"/>
    </inertial>
    <visual>
      <origin rpy="0 1.5707 0" xyz="0 0 0"/>
      <geometry>
        <cylinder radius="0.025" length="0.025"/>
      </geometry>
       <material name="scarlet"/>
    </visual>
    <collision>
      <origin rpy="0 1.5707 0" xyz="0 0 0"/>
      <geometry>
        <cylinder radius="0.025" length="0.025"/>
      </geometry>
    </collision>
</link>

<joint name="right_joint3" type="revolute">
    <parent link="right_link3"/>
    <child link="right_jlink3"/>
    <origin rpy="0 0 0" xyz="0 0.0 -0.1"/> 
    <axis xyz="1 0 0"/>
    <limit lower="-3.1415" upper="3.1415" effort="1.4" velocity="0.25"/>  
  </joint>

  <link name="right_link4">
    <inertial>
      <origin rpy="0 0 0" xyz="0 0 0"/>
       <mass value=".000000001"/>
       <inertia ixx="0" ixy="0" ixz="0" iyy="0" iyz="0" izz="0"/>
    </inertial>
    <visual>
      <origin rpy="0 0 0" xyz="0 0 0"/>
      <geometry>
       <cylinder radius="0.03" length="0.4"/>
      </geometry>
       <material name="silver"/> 
    </visual>
    <collision>
      <origin rpy="0 0 0" xyz="0 0 0"/>
      <geometry>
       <cylinder radius="0.03" length="0.4"/>
      </geometry>
    </collision>
</link>

<joint name="right_joint4f" type="fixed">
    <parent link="right_jlink3"/>
    <child link="right_link4"/>
    <origin rpy="0 0 0" xyz="0 0  -0.2"/>   
</joint>

<link name="right_jlink4">
    <inertial>
      <origin rpy="0 0 0" xyz="0.107996 0.000521 -0.017765"/>
      <mass value="0.550582"/>
      <inertia ixx="0.000476" ixy="-2.9e-05" ixz="0.001403" iyy="0.009564" iyz="-1.5e-05" izz="-9e-06"/>
    </inertial>
    <visual>
      <origin rpy="0 0 0 " xyz="0 0 0"/>
      <geometry>
        <cylinder radius="0.025" length="0.025"/>
      </geometry>
      <material name="scarlet"/> 
    </visual>
    <collision>
      <origin rpy="0 0 0" xyz="0 0 0"/>
      <geometry>
        <cylinder radius="0.025" length="0.025"/>
      </geometry>
    </collision>
</link>

<joint name="right_joint4" type="revolute">
    <origin rpy="0 0 0" xyz="0.0 0.0 -0.2"/>
    <parent link="right_link4"/>
    <child link="right_jlink4"/>
    <axis xyz="0 0 1"/>
    <limit effort="1.4" lower="-1.57" upper="1.57" velocity="10"/>
  </joint>

<link name="right_wrist">
    <inertial>
      <origin rpy="0 0 0" xyz="0.107996 0.000521 -0.017765"/>
      <mass value="0.550582"/>
      <inertia ixx="0.000476" ixy="-2.9e-05" ixz="0.001403" iyy="0.009564" iyz="-1.5e-05" izz="-9e-06"/>
    </inertial>
    <visual>
      <origin rpy="0 1.5707 1.5707 " xyz="0 0 0"/>
      <geometry>
        <cylinder radius="0.025" length="0.05"/>
      </geometry>
      <material name="grey"/>
    </visual>
    <collision>
      <origin rpy="0 1.5707 1.5707" xyz="0 0 0"/>
      <geometry>
        <cylinder radius="0.025" length="0.05"/>
      </geometry>
    </collision>
  </link>
  <joint name="right_wrist_joint" type="revolute">
    <origin rpy="0 1.5707 0" xyz="0.0 0.0 -0.025"/>
    <parent link="right_jlink4"/>
    <child link="right_wrist"/>
    <axis xyz="0 1 0"/>
    <limit effort="1.4" lower="-1.57" upper="1.57" velocity="10"/>
  </joint>

  <link name="right_gripper_base">
    <inertial>
      <origin rpy="0 0 0" xyz="0 0 0"/>
      <mass value="0.2"/>
      <inertia ixx="0.0001" ixy="0" ixz="0" iyy="0.0001" iyz="0" izz="0.0001"/>
    </inertial>
    <visual>
      <origin rpy="0 1.5707 0" xyz="0 0 0"/>
      <geometry>
        <!-- <mesh filename="/home/bill/garage/kfp_v2/morpheus/models/yumi_description/meshes/gripper/base.stl"/> -->
        <cylinder radius="0.04" length="0.1"/>
      </geometry>
      <material name="Light_Grey"/>
    </visual>
    <collision>
      <origin rpy="0 1.5707 0" xyz="0 0 0"/>
      <geometry>
        <!-- <mesh filename="/home/bill/garage/kfp_v2/morpheus/models/yumi_description/meshes/gripper/coarse/base.stl"/> -->
       <cylinder radius="0.04" length="0.1"/>
      </geometry>
      <material name="Light_Grey"/>
    </collision>
  </link>

  <joint name="gripper_right_wrist_joint" type="revolute">
    <origin rpy="0 0 0" xyz="0.07 0 0"/>
    <parent link="right_wrist"/>
    <child link="right_gripper_base"/>
    <axis xyz="1 0 0"/>
    <limit effort="1.4" lower="-1.57" upper="1.57" velocity="10"/>
  </joint>

  <link name="right_gripper_ee">
    <inertial>
      <origin rpy="0 0 0" xyz="0 0 0"/>
      <mass value="0.2"/>
      <inertia ixx="0.0001" ixy="0" ixz="0" iyy="0.0001" iyz="0" izz="0.0001"/>
    </inertial>
    <visual>
      <origin rpy="0 1.5707 0" xyz="0 0 0"/>
      <geometry>        
       <cylinder radius="0.025" length="0.025"/>
      </geometry>
      <material name="scarlet"/>
    </visual>
    <collision>
      <origin rpy="0 1.5707 0" xyz="0 0 0"/>
      <geometry>
       <cylinder radius="0.025" length="0.025"/>
      </geometry> 
    </collision>
  </link>
  <joint name="right_gripper_baseee_to_gripper_base" type="fixed">
    <origin rpy="0 0 0" xyz="0.05125 0.0 0"/>
    <parent link="right_gripper_base"/>
    <child link="right_gripper_ee"/>
  </joint>









  
    
  <joint name="hip_abduction_left" type="fixed">
    <origin rpy="1.57079632679 -1.57079632679 -1.57079632679" xyz="-0.001 0.091 0"/>
    <axis xyz="0 0 1"/>
    <parent link="torso"/>
    <child link="left_hip_roll"/>
    <limit effort="1.4" lower="-1.0472" upper="1.0472" velocity="12.15"/>
  </joint>
  <joint name="hip_rotation_left" type="fixed">
    <origin rpy="0 -1.57079632679 0" xyz="-0.0505 0 0.044"/>
    <axis xyz="0 0 1"/>
    <parent link="left_hip_roll"/>
    <child link="left_hip_yaw"/>
    <limit effort="1.4" lower="-0.698132" upper="0.698132" velocity="12.15"/>
  </joint>
  <joint name="hip_flexion_left" type="fixed">
    <origin rpy="-1.57079632679 -0.785398163397 3.14159265359" xyz="0 0.004 0.068"/>
    <axis xyz="0 0 -1"/>
    <parent link="left_hip_yaw"/>
    <child link="left_hip_pitch"/>
    <limit effort="12.5" lower="-1.0472" upper="1.57079632679" velocity="8.5"/>
  </joint>
  <joint name="knee_joint_left" type="fixed">
    <origin rpy="0 0 -1.17079632679" xyz="0.12 0 0.0045"/>
    <axis xyz="0 0 1"/>
    <parent link="left_hip_pitch"/>
    <child link="left_knee"/>
    <limit effort="12.5" lower="-1.2392" upper="0.8727" velocity="8.5085"/>
  </joint>
  <joint name="knee_to_shin_left" type="fixed">
    <origin rpy="0 0 0" xyz="0.060677 0.047406 0"/>
    <axis xyz="0 0 1"/>
    <parent link="left_knee"/>
    <child link="left_shin"/>
    <limit effort="0" lower="-0.35" upper="0.35" velocity="10"/>
  </joint>
  <joint name="shin_to_tarsus_left" type="fixed">
    <origin rpy="0 0 1.7976891" xyz="0.434759 0.02 0"/>
    <axis xyz="0 0 1"/>
    <parent link="left_shin"/>
    <child link="left_tarsus"/>
    <limit effort="0" lower="-0.8779" upper="1.2497" velocity="20"/>
  </joint>
  <joint name="toe_pitch_joint_left" type="fixed">
    <origin rpy="0 0 0.7" xyz="0.408 -0.04 0"/>
    <axis xyz="0 0 1"/>
    <parent link="left_tarsus"/>
    <child link="left_toe_pitch"/>
    <limit effort="0.9" lower="-0.785398163397" upper="0.785398163397" velocity="11.5"/>
  </joint>
  <joint name="toe_roll_joint_left" type="fixed">
    <origin rpy="0 1.57079632679 0" xyz="0 0 0"/>
    <axis xyz="0 0 1"/>
    <parent link="left_toe_pitch"/>
    <child link="left_toe_roll"/>
    <limit effort="0.9" lower="-0.6109" upper="0.6109" velocity="11.5"/>
  </joint>
  

  <joint name="hip_abduction_right" type="fixed">
    <origin rpy="-1.57079632679 -1.57079632679 1.57079632679" xyz="-0.001 -0.091 0"/>
    <axis xyz="0 0 1"/>
    <parent link="torso"/>
    <child link="right_hip_roll"/>
    <limit effort="1.4" lower="-1.0472" upper="1.0472" velocity="12.15"/>
  </joint>
  <joint name="hip_rotation_right" type="fixed">
    <origin rpy="0 -1.57079632679 0" xyz="-0.0505 0 0.044"/>
    <axis xyz="0 0 1"/>
    <parent link="right_hip_roll"/>
    <child link="right_hip_yaw"/>
    <limit effort="1.4" lower="-0.698132" upper="0.698132" velocity="12.15"/>
  </joint>
  <joint name="hip_flexion_right" type="fixed">
    <origin rpy="1.57079632679 -0.785398163397 -3.14159265359" xyz="0 -0.004 0.068"/>
    <axis xyz="0 0 -1"/>
    <parent link="right_hip_yaw"/>
    <child link="right_hip_pitch"/>
    <limit effort="12.5" lower="-1.57079632679" upper="1.0472" velocity="8.5"/>
  </joint>
  <joint name="knee_joint_right" type="fixed">
    <origin rpy="0 0 1.17079632679" xyz="0.12 0 0.0045"/>
    <axis xyz="0 0 1"/>
    <parent link="right_hip_pitch"/>
    <child link="right_knee"/>
    <limit effort="12.5" lower="-0.8727" upper="1.2392" velocity="8.5085"/>
  </joint>
  <joint name="knee_to_shin_right" type="fixed">
    <origin rpy="0 0 0" xyz="0.060677 -0.047406 0"/>
    <axis xyz="0 0 1"/>
    <parent link="right_knee"/>
    <child link="right_shin"/>
    <limit effort="0" lower="-0.35" upper="0.35" velocity="10"/>
  </joint>
  <joint name="shin_to_tarsus_right" type="fixed">
    <origin rpy="0 0 -1.7976891" xyz="0.434759 -0.02 0"/>
    <axis xyz="0 0 1"/>
    <parent link="right_shin"/>
    <child link="right_tarsus"/>
    <limit effort="0" lower="-1.2497" upper="0.8779" velocity="20"/>
  </joint>
  <joint name="toe_pitch_joint_right" type="fixed">
    <origin rpy="0 0 -0.7" xyz="0.408 0.04 0"/>
    <axis xyz="0 0 1"/>
    <parent link="right_tarsus"/>
    <child link="right_toe_pitch"/>
    <limit effort="0.9" lower="-0.785398163397" upper="0.785398163397" velocity="11.5"/>
  </joint>
  <joint name="toe_roll_joint_right" type="fixed">
    <origin rpy="0 1.57079632679 0" xyz="0 0 0"/>
    <axis xyz="0 0 1"/>
    <parent link="right_toe_pitch"/>
    <child link="right_toe_roll"/>
    <limit effort="0.9" lower="-0.6109" upper="0.6109" velocity="11.5"/>
  </joint>

   

<!-- joint to freight base -->
<joint name="digit_to_freight" type="fixed">
    <origin rpy="0 0 0" xyz="0 0  0.9"/>
    <parent link="base_link"/>
    <child link="torso"/>
</joint>

 

<link name="base_link">
    <inertial>
      <origin rpy="0 0 0" xyz="0 0 0"/>
      <mass value="15.028392"/>
      <inertia ixx="0.0045" ixy="0" ixz="0" iyy="0.005" iyz="0" izz="0.0045" />
    </inertial>
    <visual>
      <origin rpy="1.57 0 1.57" xyz="0.33 -0.25 0.0"/>
      <geometry>
        <mesh filename="/home/bill/garage/kfp_v2/digit/models/hoverboard/meshes/base.obj" scale="0.025 0.025 0.025"/> 
      </geometry>
      <material name="scarlet"/> 
    </visual>
    <collision>
      <origin rpy="1.57  0 1.57 " xyz="0 0 0"/>
      <geometry>
        <!-- <mesh filename="meshes/base.obj" scale="0.05 0.05 0.05"/> -->
        <box size="0.5 0.15 0.5"/>
      </geometry>
    </collision>
</link>

<link name="right_wheel">
    <inertial>
      <origin rpy="0 0 0" xyz="0 0 0"/>
      <mass value="4.028392"/>
      <inertia ixx="0.0045" ixy="0" ixz="0" iyy="0.005" iyz="0" izz="0.0045" />
    </inertial>
    <visual>
      <origin rpy="1.57 0 1.57" xyz="-0.33 0.255 0.0"/>
      <geometry>
        <mesh filename="/home/bill/garage/kfp_v2/digit/models/hoverboard/meshes/wheel.stl" scale="0.025 0.025 0.025"/>
       </geometry>
      <material name="black">
        <color rgba="0.2 0.2 0.2 1"/>
      </material>
    </visual>
    <collision>
      <origin rpy="1.57  0 1.57 " xyz="0 0 0"/>
      <geometry>
        <box size="0.005 0.005 0.005"/>

       </geometry>
    </collision>
</link>

<joint name="wheelr_to_base" type="continuous">
  <origin rpy="0 0 3.14159265359" xyz="0 0 0"/>
    <axis xyz="0 1 0"/>
    <parent link="base_link"/>
    <child link="right_wheel"/>
    <limit effort="8.85" velocity="34.8" />
</joint>

<link name="left_wheel">
    <inertial>
      <origin rpy="0 0 0" xyz="0 0 0"/>
      <mass value="4.028392"/>
      <inertia ixx="0.0045" ixy="0" ixz="0" iyy="0.005" iyz="0" izz="0.0045" />
    </inertial>
    <visual>
      <origin rpy="1.57 0 1.57" xyz="0.33 -0.74 0.01"/>
      <geometry>
        <mesh filename="/home/bill/garage/kfp_v2/digit/models/hoverboard/meshes/wheel.stl" scale="0.025 0.025 0.025"/>
       </geometry>
      <material name="black">
        <color rgba="0.2 0.2 0.2 1"/>
      </material>
    </visual>
    <collision>
      <origin rpy="1.57  0 1.57 " xyz="0 0 0"/>
      <geometry>
       <box size="0.005 0.005 0.005"/>

       </geometry>
    </collision>
</link>

<joint name="wheell_to_base" type="fixed">
  <origin rpy="0 0 0" xyz="0 1.0 0"/>
    <axis xyz="0 1 0"/>
    <parent link="base_link"/>
    <child link="left_wheel"/>
    <limit effort="8.85" velocity="34.8" />
</joint>

<link name="torso_camera_link">
    <inertial>
      <origin rpy="0 0 0" xyz="-0.0306228970175641 0.0007091682908278 0.0551974119471302" />
      <mass value="0.00833634573995571" />
      <inertia ixx="1.01866461240801E-06" ixy="-5.88447626567756E-08" ixz="7.83857244757914E-08" iyy="5.10039589974707E-07" iyz="-7.12664289617235E-09" izz="1.28270671527309E-06" />
    </inertial>
    <visual>
      <origin rpy="0 0 0" xyz="0 0 0" />
      <geometry> 
       <box size="0.02 0.02 0.1"/>
      </geometry>
      <material name="black">
        <color rgba="0.2 0.2 0.2 1" />
      </material>
    </visual>
    <collision>
      <origin rpy="0 0 0" xyz="0. 0 0" />
      <geometry>
       <box size="0.02 0.02 0.1"/>
      </geometry>
    </collision>
  </link> 
  <joint name="camera_joint" type="fixed">
    <origin rpy="1.5707 0.866 0" xyz="0.08 0 0.5" />
    <parent link="torso" />
    <child link="torso_camera_link" />
  </joint> 


</robot>